Workbook

Sheet Controle
B2: Controle Capex | M2: Suporte lista
B3: # | C3: UFV | D3: CNPJ | E3: Unidade | F3: Frente | G3: Portfólio | H3: Contrato | I3: Medição | J3: Saldo a medir | K3: Avanço | M3: Natureza
B4: 1 | C4: Diamantina 1 | D4: MORI GERACAO II | E4: Mori II | F4: 3 | G4: Mori | H4: =SUMIFS('Controle Projetos_Ciclo2'!$O:$O,'Controle Projetos_Ciclo2'!$B:$B,$C4,'Controle Projetos_Ciclo2'!$F:$F,"Total") -> 0 | I4: =SUMIFS('Controle Projetos_Ciclo2'!$R:$R,'Controle Projetos_Ciclo2'!$B:$B,$C4,'Controle Projetos_Ciclo2'!$F:$F,"Total") -> 0 | J4: =SUMIFS('Controle Projetos_Ciclo2'!S:S,'Controle Projetos_Ciclo2'!$B:$B,$C4,'Controle Projetos_Ciclo2'!$F:$F,"Total") -> 0 | K4: =IFERROR(I4/H4,0) -> 0 | M4: Conexão AT - Obras
B5: =B4+1 -> 2 | C5: Diamantina 2 | D5: MORI GERACAO II | E5: Mori II | F5: 3 | G5: Mori | H5: =SUMIFS('Controle Projetos_Ciclo2'!$O:$O,'Controle Projetos_Ciclo2'!$B:$B,$C5,'Controle Projetos_Ciclo2'!$F:$F,"Total") -> 2348118.8 | I5: =SUMIFS('Controle Projetos_Ciclo2'!$R:$R,'Controle Projetos_Ciclo2'!$B:$B,$C5,'Controle Projetos_Ciclo2'!$F:$F,"Total") -> 2290918.8 | J5: =SUMIFS('Controle Projetos_Ciclo2'!S:S,'Controle Projetos_Ciclo2'!$B:$B,$C5,'Controle Projetos_Ciclo2'!$F:$F,"Total") -> 57200 | K5: =IFERROR(I5/H5,0) -> 0.97564007 | M5: Conexão MT - Obras
B6: =B5+1 -> 3 | C6: Frei Inocêncio 1 | D6: MORI GERACAO II | E6: Mori II | F6: Weg | G6: Mori | H6: =SUMIFS('Controle Projetos_Ciclo2'!$O:$O,'Controle Projetos_Ciclo2'!$B:$B,$C6,'Controle Projetos_Ciclo2'!$F:$F,"Total") -> 0 | I6: =SUMIFS('Controle Projetos_Ciclo2'!$R:$R,'Controle Projetos_Ciclo2'!$B:$B,$C6,'Controle Projetos_Ciclo2'!$F:$F,"Total") -> 0 | J6: =SUMIFS('Controle Projetos_Ciclo2'!S:S,'Controle Projetos_Ciclo2'!$B:$B,$C6,'Controle Projetos_Ciclo2'!$F:$F,"Total") -> 0 | K6: =IFERROR(I6/H6,0) -> 0 | M6: Construção - Serviços de Construção
B7: =B6+1 -> 4 | C7: Lagoa Formosa 1 | D7: MORI GERACAO II | E7: Mori II | F7: 1 | G7: Mori | H7: =SUMIFS('Controle Projetos_Ciclo2'!$O:$O,'Controle Projetos_Ciclo2'!$B:$B,$C7,'Controle Projetos_Ciclo2'!$F:$F,"Total") -> 0 | I7: =SUMIFS('Controle Projetos_Ciclo2'!$R:$R,'Controle Projetos_Ciclo2'!$B:$B,$C7,'Controle Projetos_Ciclo2'!$F:$F,"Total") -> 0 | J7: =SUMIFS('Controle Projetos_Ciclo2'!S:S,'Controle Projetos_Ciclo2'!$B:$B,$C7,'Controle Projetos_Ciclo2'!$F:$F,"Total") -> 0 | K7: =IFERROR(I7/H7,0) -> 0 | M7: Construção - Serviços de Construção - Substituição
B8: =B7+1 -> 5 | C8: Nova Ponte 1 | D8: MORI GERACAO II | E8: Mori II | F8: Weg | G8: Mori | H8: =SUMIFS('Controle Projetos_Ciclo2'!$O:$O,'Controle Projetos_Ciclo2'!$B:$B,$C8,'Controle Projetos_Ciclo2'!$F:$F,"Total") -> 0 | I8: =SUMIFS('Controle Projetos_Ciclo2'!$R:$R,'Controle Projetos_Ciclo2'!$B:$B,$C8,'Controle Projetos_Ciclo2'!$F:$F,"Total") -> 0 | J8: =SUMIFS('Controle Projetos_Ciclo2'!S:S,'Controle Projetos_Ciclo2'!$B:$B,$C8,'Controle Projetos_Ciclo2'!$F:$F,"Total") -> 0 | K8: =IFERROR(I8/H8,0) -> 0 | M8: Construção - RDA Interno
B9: =B8+1 -> 6 | C9: Paracatu 8 | D9: MORI GERACAO II | E9: Mori II | F9: Weg | G9: Mori | H9: =SUMIFS('Controle Projetos_Ciclo2'!$O:$O,'Controle Projetos_Ciclo2'!$B:$B,$C9,'Controle Projetos_Ciclo2'!$F:$F,"Total") -> 0 | I9: =SUMIFS('Controle Projetos_Ciclo2'!$R:$R,'Controle Projetos_Ciclo2'!$B:$B,$C9,'Controle Projetos_Ciclo2'!$F:$F,"Total") -> 0 | J9: =SUMIFS('Controle Projetos_Ciclo2'!S:S,'Controle Projetos_Ciclo2'!$B:$B,$C9,'Controle Projetos_Ciclo2'!$F:$F,"Total") -> 0 | K9: =IFERROR(I9/H9,0) -> 0 | M9: Full EPC - Contrato
B10: =B9+1 -> 7 | C10: Patos de Minas 1 | D10: MORI GERACAO II | E10: Mori II | F10: 1 | G10: Mori | H10: =SUMIFS('Controle Projetos_Ciclo2'!$O:$O,'Controle Projetos_Ciclo2'!$B:$B,$C10,'Controle Projetos_Ciclo2'!$F:$F,"Total") -> 0 | I10: =SUMIFS('Controle Projetos_Ciclo2'!$R:$R,'Controle Projetos_Ciclo2'!$B:$B,$C10,'Controle Projetos_Ciclo2'!$F:$F,"Total") -> 0 | J10: =SUMIFS('Controle Projetos_Ciclo2'!S:S,'Controle Projetos_Ciclo2'!$B:$B,$C10,'Controle Projetos_Ciclo2'!$F:$F,"Total") -> 0 | K10: =IFERROR(I10/H10,0) -> 0 | M10: Equipamentos Curva A - Outros (Transformadores)
B11: =B10+1 -> 8 | C11: Patos de Minas 3 | D11: MORI GERACAO II | E11: Mori II | F11: 2 | G11: Mori | H11: =SUMIFS('Controle Projetos_Ciclo2'!$O:$O,'Controle Projetos_Ciclo2'!$B:$B,$C11,'Controle Projetos_Ciclo2'!$F:$F,"Total") -> 0 | I11: =SUMIFS('Controle Projetos_Ciclo2'!$R:$R,'Controle Projetos_Ciclo2'!$B:$B,$C11,'Controle Projetos_Ciclo2'!$F:$F,"Total") -> 0 | J11: =SUMIFS('Controle Projetos_Ciclo2'!S:S,'Controle Projetos_Ciclo2'!$B:$B,$C11,'Controle Projetos_Ciclo2'!$F:$F,"Total") -> 0 | K11: =IFERROR(I11/H11,0) -> 0 | M11: Equipamentos Curva A - Outros (Cabine + Skid)
B12: =B11+1 -> 9 | C12: Patos de Minas 4 | D12: MORI GERACAO II | E12: Mori II | F12: 1 | G12: Mori | H12: =SUMIFS('Controle Projetos_Ciclo2'!$O:$O,'Controle Projetos_Ciclo2'!$B:$B,$C12,'Controle Projetos_Ciclo2'!$F:$F,"Total") -> 0 | I12: =SUMIFS('Controle Projetos_Ciclo2'!$R:$R,'Controle Projetos_Ciclo2'!$B:$B,$C12,'Controle Projetos_Ciclo2'!$F:$F,"Total") -> 0 | J12: =SUMIFS('Controle Projetos_Ciclo2'!S:S,'Controle Projetos_Ciclo2'!$B:$B,$C12,'Controle Projetos_Ciclo2'!$F:$F,"Total") -> 0 | K12: =IFERROR(I12/H12,0) -> 0 | M12: Equipamentos Curva A - Outros (Cabine + Skid + Transformador)
B13: =B12+1 -> 10 | C13: Patos de Minas 7 | D13: MORI GERACAO II | E13: Mori II | F13: 1 | G13: Mori | H13: =SUMIFS('Controle Projetos_Ciclo2'!$O:$O,'Controle Projetos_Ciclo2'!$B:$B,$C13,'Controle Projetos_Ciclo2'!$F:$F,"Total") -> 0 | I13: =SUMIFS('Controle Projetos_Ciclo2'!$R:$R,'Controle Projetos_Ciclo2'!$B:$B,$C13,'Controle Projetos_Ciclo2'!$F:$F,"Total") -> 0 | J13: =SUMIFS('Controle Projetos_Ciclo2'!S:S,'Controle Projetos_Ciclo2'!$B:$B,$C13,'Controle Projetos_Ciclo2'!$F:$F,"Total") -> 0 | K13: =IFERROR(I13/H13,0) -> 0 | M13: Desenvolvimento de projeto - Projetos - (Eng° Proprietario)
B14: =B13+1 -> 11 | C14: Patos de Minas 8 | D14: MORI GERACAO II | E14: Mori II | F14: 1 | G14: Mori | H14: =SUMIFS('Controle Projetos_Ciclo2'!$O:$O,'Controle Projetos_Ciclo2'!$B:$B,$C14,'Controle Projetos_Ciclo2'!$F:$F,"Total") -> 0 | I14: =SUMIFS('Controle Projetos_Ciclo2'!$R:$R,'Controle Projetos_Ciclo2'!$B:$B,$C14,'Controle Projetos_Ciclo2'!$F:$F,"Total") -> 0 | J14: =SUMIFS('Controle Projetos_Ciclo2'!S:S,'Controle Projetos_Ciclo2'!$B:$B,$C14,'Controle Projetos_Ciclo2'!$F:$F,"Total") -> 0 | K14: =IFERROR(I14/H14,0) -> 0 | M14: Desenvolvimento de projeto - Projetos - Executivos
B15: =B14+1 -> 12 | C15: Patrocínio 2 | D15: MORI GERACAO II | E15: Mori II | F15: 1 | G15: Mori | H15: =SUMIFS('Controle Projetos_Ciclo2'!$O:$O,'Controle Projetos_Ciclo2'!$B:$B,$C15,'Controle Projetos_Ciclo2'!$F:$F,"Total") -> 0 | I15: =SUMIFS('Controle Projetos_Ciclo2'!$R:$R,'Controle Projetos_Ciclo2'!$B:$B,$C15,'Controle Projetos_Ciclo2'!$F:$F,"Total") -> 0 | J15: =SUMIFS('Controle Projetos_Ciclo2'!S:S,'Controle Projetos_Ciclo2'!$B:$B,$C15,'Controle Projetos_Ciclo2'!$F:$F,"Total") -> 0 | K15: =IFERROR(I15/H15,0) -> 0 | M15: Desenvolvimento de projeto - Projetos Básica
B16: =B15+1 -> 13 | C16: Patrocínio 3 | D16: MORI GERACAO II | E16: Mori II | F16: 1 | G16: Mori | H16: =SUMIFS('Controle Projetos_Ciclo2'!$O:$O,'Controle Projetos_Ciclo2'!$B:$B,$C16,'Controle Projetos_Ciclo2'!$F:$F,"Total") -> 0 | I16: =SUMIFS('Controle Projetos_Ciclo2'!$R:$R,'Controle Projetos_Ciclo2'!$B:$B,$C16,'Controle Projetos_Ciclo2'!$F:$F,"Total") -> 0 | J16: =SUMIFS('Controle Projetos_Ciclo2'!S:S,'Controle Projetos_Ciclo2'!$B:$B,$C16,'Controle Projetos_Ciclo2'!$F:$F,"Total") -> 0 | K16: =IFERROR(I16/H16,0) -> 0 | M16: Desenvolvimento de projeto - Projetos Detalhada
B17: =B16+1 -> 14 | C17: Varjão de Minas 1 | D17: MORI GERACAO II | E17: Mori II | F17: Weg | G17: Mori | H17: =SUMIFS('Controle Projetos_Ciclo2'!$O:$O,'Controle Projetos_Ciclo2'!$B:$B,$C17,'Controle Projetos_Ciclo2'!$F:$F,"Total") -> 0 | I17: =SUMIFS('Controle Projetos_Ciclo2'!$R:$R,'Controle Projetos_Ciclo2'!$B:$B,$C17,'Controle Projetos_Ciclo2'!$F:$F,"Total") -> 0 | J17: =SUMIFS('Controle Projetos_Ciclo2'!S:S,'Controle Projetos_Ciclo2'!$B:$B,$C17,'Controle Projetos_Ciclo2'!$F:$F,"Total") -> 0 | K17: =IFERROR(I17/H17,0) -> 0 | M17: Desenvolvimento de projeto - Ambiental / Outros
B18: =B17+1 -> 15 | C18: Varjão de Minas 4 | D18: MORI GERACAO II | E18: Mori II | F18: 2 | G18: Mori | H18: =SUMIFS('Controle Projetos_Ciclo2'!$O:$O,'Controle Projetos_Ciclo2'!$B:$B,$C18,'Controle Projetos_Ciclo2'!$F:$F,"Total") -> 0 | I18: =SUMIFS('Controle Projetos_Ciclo2'!$R:$R,'Controle Projetos_Ciclo2'!$B:$B,$C18,'Controle Projetos_Ciclo2'!$F:$F,"Total") -> 0 | J18: =SUMIFS('Controle Projetos_Ciclo2'!S:S,'Controle Projetos_Ciclo2'!$B:$B,$C18,'Controle Projetos_Ciclo2'!$F:$F,"Total") -> 0 | K18: =IFERROR(I18/H18,0) -> 0 | M18: Desenvolvimento de projeto - Coordenograma
B19: =B18+1 -> 16 | C19: Buritizeiro 1 | D19: ESTRELA DO NORTE | E19: EDN | F19: 1 | G19: Apolo | H19: =SUMIFS('Controle Projetos_Ciclo2'!$O:$O,'Controle Projetos_Ciclo2'!$B:$B,$C19,'Controle Projetos_Ciclo2'!$F:$F,"Total") -> 0 | I19: =SUMIFS('Controle Projetos_Ciclo2'!$R:$R,'Controle Projetos_Ciclo2'!$B:$B,$C19,'Controle Projetos_Ciclo2'!$F:$F,"Total") -> 0 | J19: =SUMIFS('Controle Projetos_Ciclo2'!S:S,'Controle Projetos_Ciclo2'!$B:$B,$C19,'Controle Projetos_Ciclo2'!$F:$F,"Total") -> 0 | K19: =IFERROR(I19/H19,0) -> 0 | M19: Sistemas de Monitoramento - Supervisório
B20: =B19+1 -> 17 | C20: Buritizeiro 2 | D20: ESTRELA DO NORTE | E20: EDN | F20: 1 | G20: Apolo | H20: =SUMIFS('Controle Projetos_Ciclo2'!$O:$O,'Controle Projetos_Ciclo2'!$B:$B,$C20,'Controle Projetos_Ciclo2'!$F:$F,"Total") -> 0 | I20: =SUMIFS('Controle Projetos_Ciclo2'!$R:$R,'Controle Projetos_Ciclo2'!$B:$B,$C20,'Controle Projetos_Ciclo2'!$F:$F,"Total") -> 0 | J20: =SUMIFS('Controle Projetos_Ciclo2'!S:S,'Controle Projetos_Ciclo2'!$B:$B,$C20,'Controle Projetos_Ciclo2'!$F:$F,"Total") -> 0 | K20: =IFERROR(I20/H20,0) -> 0 | M20: Sistemas de Monitoramento - Estações Solarimétricas
B21: =B20+1 -> 18 | C21: Guarda-Mor | D21: ESTRELA DO NORTE | E21: EDN | F21: Weg | G21: Apolo | H21: =SUMIFS('Controle Projetos_Ciclo2'!$O:$O,'Controle Projetos_Ciclo2'!$B:$B,$C21,'Controle Projetos_Ciclo2'!$F:$F,"Total") -> 0 | I21: =SUMIFS('Controle Projetos_Ciclo2'!$R:$R,'Controle Projetos_Ciclo2'!$B:$B,$C21,'Controle Projetos_Ciclo2'!$F:$F,"Total") -> 0 | J21: =SUMIFS('Controle Projetos_Ciclo2'!S:S,'Controle Projetos_Ciclo2'!$B:$B,$C21,'Controle Projetos_Ciclo2'!$F:$F,"Total") -> 0 | K21: =IFERROR(I21/H21,0) -> 0 | M21: Sistemas de Monitoramento - CFTV
B22: =B21+1 -> 19 | C22: Indaiabira 1 | D22: ESTRELA DO NORTE | E22: EDN | F22: Weg | G22: Apolo | H22: =SUMIFS('Controle Projetos_Ciclo2'!$O:$O,'Controle Projetos_Ciclo2'!$B:$B,$C22,'Controle Projetos_Ciclo2'!$F:$F,"Total") -> 0 | I22: =SUMIFS('Controle Projetos_Ciclo2'!$R:$R,'Controle Projetos_Ciclo2'!$B:$B,$C22,'Controle Projetos_Ciclo2'!$F:$F,"Total") -> 0 | J22: =SUMIFS('Controle Projetos_Ciclo2'!S:S,'Controle Projetos_Ciclo2'!$B:$B,$C22,'Controle Projetos_Ciclo2'!$F:$F,"Total") -> 0 | K22: =IFERROR(I22/H22,0) -> 0 | M22: Serviços Auxiliares - Drenagem
B23: =B22+1 -> 20 | C23: Indaiabira 2 | D23: ESTRELA DO NORTE | E23: EDN | F23: Weg | G23: Apolo | H23: =SUMIFS('Controle Projetos_Ciclo2'!$O:$O,'Controle Projetos_Ciclo2'!$B:$B,$C23,'Controle Projetos_Ciclo2'!$F:$F,"Total") -> 0 | I23: =SUMIFS('Controle Projetos_Ciclo2'!$R:$R,'Controle Projetos_Ciclo2'!$B:$B,$C23,'Controle Projetos_Ciclo2'!$F:$F,"Total") -> 0 | J23: =SUMIFS('Controle Projetos_Ciclo2'!S:S,'Controle Projetos_Ciclo2'!$B:$B,$C23,'Controle Projetos_Ciclo2'!$F:$F,"Total") -> 0 | K23: =IFERROR(I23/H23,0) -> 0 | M23: Serviços Auxiliares - Terraplanagem
B24: =B23+1 -> 21 | C24: Indaiabira 3 | D24: ESTRELA DO NORTE | E24: EDN | F24: 1 | G24: Apolo | H24: =SUMIFS('Controle Projetos_Ciclo2'!$O:$O,'Controle Projetos_Ciclo2'!$B:$B,$C24,'Controle Projetos_Ciclo2'!$F:$F,"Total") -> 0 | I24: =SUMIFS('Controle Projetos_Ciclo2'!$R:$R,'Controle Projetos_Ciclo2'!$B:$B,$C24,'Controle Projetos_Ciclo2'!$F:$F,"Total") -> 0 | J24: =SUMIFS('Controle Projetos_Ciclo2'!S:S,'Controle Projetos_Ciclo2'!$B:$B,$C24,'Controle Projetos_Ciclo2'!$F:$F,"Total") -> 0 | K24: =IFERROR(I24/H24,0) -> 0 | M24: Serviços Auxiliares - Supressão Vegetal
B25: =B24+1 -> 22 | C25: Indaiabira 4 | D25: ESTRELA DO NORTE | E25: EDN | F25: 1 | G25: Apolo | H25: =SUMIFS('Controle Projetos_Ciclo2'!$O:$O,'Controle Projetos_Ciclo2'!$B:$B,$C25,'Controle Projetos_Ciclo2'!$F:$F,"Total") -> 0 | I25: =SUMIFS('Controle Projetos_Ciclo2'!$R:$R,'Controle Projetos_Ciclo2'!$B:$B,$C25,'Controle Projetos_Ciclo2'!$F:$F,"Total") -> 0 | J25: =SUMIFS('Controle Projetos_Ciclo2'!S:S,'Controle Projetos_Ciclo2'!$B:$B,$C25,'Controle Projetos_Ciclo2'!$F:$F,"Total") -> 0 | K25: =IFERROR(I25/H25,0) -> 0 | M25: RDR-Rede de Distribuição Rural
B26: =B25+1 -> 23 | C26: Jaboticatubas | D26: ESTRELA DO NORTE | E26: EDN | F26: 3 | G26: Apolo | H26: =SUMIFS('Controle Projetos_Ciclo2'!$O:$O,'Controle Projetos_Ciclo2'!$B:$B,$C26,'Controle Projetos_Ciclo2'!$F:$F,"Total") -> 0 | I26: =SUMIFS('Controle Projetos_Ciclo2'!$R:$R,'Controle Projetos_Ciclo2'!$B:$B,$C26,'Controle Projetos_Ciclo2'!$F:$F,"Total") -> 0 | J26: =SUMIFS('Controle Projetos_Ciclo2'!S:S,'Controle Projetos_Ciclo2'!$B:$B,$C26,'Controle Projetos_Ciclo2'!$F:$F,"Total") -> 0 | K26: =IFERROR(I26/H26,0) -> 0 | M26: Escopo COMERC
B27: =B26+1 -> 24 | C27: São Sebastião 0 | D27: ESTRELA DO NORTE | E27: EDN | F27: 3 | G27: Apolo | H27: =SUMIFS('Controle Projetos_Ciclo2'!$O:$O,'Controle Projetos_Ciclo2'!$B:$B,$C27,'Controle Projetos_Ciclo2'!$F:$F,"Total") -> 0 | I27: =SUMIFS('Controle Projetos_Ciclo2'!$R:$R,'Controle Projetos_Ciclo2'!$B:$B,$C27,'Controle Projetos_Ciclo2'!$F:$F,"Total") -> 0 | J27: =SUMIFS('Controle Projetos_Ciclo2'!S:S,'Controle Projetos_Ciclo2'!$B:$B,$C27,'Controle Projetos_Ciclo2'!$F:$F,"Total") -> 0 | K27: =IFERROR(I27/H27,0) -> 0 | M27: Não Controlado
B28: =B27+1 -> 25 | C28: Divinópolis 1 | D28: ESTRELA DO NORTE | E28: EDN | F28: 2 | G28: Apolo | H28: =SUMIFS('Controle Projetos_Ciclo2'!$O:$O,'Controle Projetos_Ciclo2'!$B:$B,$C28,'Controle Projetos_Ciclo2'!$F:$F,"Total") -> 0 | I28: =SUMIFS('Controle Projetos_Ciclo2'!$R:$R,'Controle Projetos_Ciclo2'!$B:$B,$C28,'Controle Projetos_Ciclo2'!$F:$F,"Total") -> 0 | J28: =SUMIFS('Controle Projetos_Ciclo2'!S:S,'Controle Projetos_Ciclo2'!$B:$B,$C28,'Controle Projetos_Ciclo2'!$F:$F,"Total") -> 0 | K28: =IFERROR(I28/H28,0) -> 0 | M28: Controle da Lais
B29: =B28+1 -> 26 | C29: Divinópolis 2 | D29: ESTRELA DO NORTE | E29: EDN | F29: 2 | G29: Apolo | H29: =SUMIFS('Controle Projetos_Ciclo2'!$O:$O,'Controle Projetos_Ciclo2'!$B:$B,$C29,'Controle Projetos_Ciclo2'!$F:$F,"Total") -> 0 | I29: =SUMIFS('Controle Projetos_Ciclo2'!$R:$R,'Controle Projetos_Ciclo2'!$B:$B,$C29,'Controle Projetos_Ciclo2'!$F:$F,"Total") -> 0 | J29: =SUMIFS('Controle Projetos_Ciclo2'!S:S,'Controle Projetos_Ciclo2'!$B:$B,$C29,'Controle Projetos_Ciclo2'!$F:$F,"Total") -> 0 | K29: =IFERROR(I29/H29,0) -> 0 | M29: Escopo COMERC - Segurança
B30: =B29+1 -> 27 | C30: Divinópolis 3 | D30: ESTRELA DO NORTE | E30: EDN | F30: 1 | G30: Apolo | H30: =SUMIFS('Controle Projetos_Ciclo2'!$O:$O,'Controle Projetos_Ciclo2'!$B:$B,$C30,'Controle Projetos_Ciclo2'!$F:$F,"Total") -> 0 | I30: =SUMIFS('Controle Projetos_Ciclo2'!$R:$R,'Controle Projetos_Ciclo2'!$B:$B,$C30,'Controle Projetos_Ciclo2'!$F:$F,"Total") -> 0 | J30: =SUMIFS('Controle Projetos_Ciclo2'!S:S,'Controle Projetos_Ciclo2'!$B:$B,$C30,'Controle Projetos_Ciclo2'!$F:$F,"Total") -> 0 | K30: =IFERROR(I30/H30,0) -> 0 | M30: Conexão MT - Obras Transferencia
B31: =B30+1 -> 28 | C31: Pedra do Indaiá 1 | D31: ESTRELA DO NORTE | E31: EDN | F31: 1 | G31: Apolo | H31: =SUMIFS('Controle Projetos_Ciclo2'!$O:$O,'Controle Projetos_Ciclo2'!$B:$B,$C31,'Controle Projetos_Ciclo2'!$F:$F,"Total") -> 0 | I31: =SUMIFS('Controle Projetos_Ciclo2'!$R:$R,'Controle Projetos_Ciclo2'!$B:$B,$C31,'Controle Projetos_Ciclo2'!$F:$F,"Total") -> 0 | J31: =SUMIFS('Controle Projetos_Ciclo2'!S:S,'Controle Projetos_Ciclo2'!$B:$B,$C31,'Controle Projetos_Ciclo2'!$F:$F,"Total") -> 0 | K31: =IFERROR(I31/H31,0) -> 0 | M31: Bases de Contaniers
B32: =B31+1 -> 29 | C32: Pedra do Indaiá 3 | D32: ESTRELA DO NORTE | E32: EDN | F32: 1 | G32: Apolo | H32: =SUMIFS('Controle Projetos_Ciclo2'!$O:$O,'Controle Projetos_Ciclo2'!$B:$B,$C32,'Controle Projetos_Ciclo2'!$F:$F,"Total") -> 0 | I32: =SUMIFS('Controle Projetos_Ciclo2'!$R:$R,'Controle Projetos_Ciclo2'!$B:$B,$C32,'Controle Projetos_Ciclo2'!$F:$F,"Total") -> 0 | J32: =SUMIFS('Controle Projetos_Ciclo2'!S:S,'Controle Projetos_Ciclo2'!$B:$B,$C32,'Controle Projetos_Ciclo2'!$F:$F,"Total") -> 0 | K32: =IFERROR(I32/H32,0) -> 0 | M32: Construção - Serviços de Construção - Ase Engenharia
B33: =B32+1 -> 30 | C33: Pedra do Indaiá 5 | D33: ESTRELA DO NORTE | E33: EDN | F33: 1 | G33: Apolo | H33: =SUMIFS('Controle Projetos_Ciclo2'!$O:$O,'Controle Projetos_Ciclo2'!$B:$B,$C33,'Controle Projetos_Ciclo2'!$F:$F,"Total") -> 0 | I33: =SUMIFS('Controle Projetos_Ciclo2'!$R:$R,'Controle Projetos_Ciclo2'!$B:$B,$C33,'Controle Projetos_Ciclo2'!$F:$F,"Total") -> 0 | J33: =SUMIFS('Controle Projetos_Ciclo2'!S:S,'Controle Projetos_Ciclo2'!$B:$B,$C33,'Controle Projetos_Ciclo2'!$F:$F,"Total") -> 0 | K33: =IFERROR(I33/H33,0) -> 0 | M33: Full EPC - Contrato Sobressalentes
B34: =B33+1 -> 31 | C34: Pains 1 | D34: ESTRELA DO NORTE | E34: EDN | F34: 3 | G34: Apolo | H34: =SUMIFS('Controle Projetos_Ciclo2'!$O:$O,'Controle Projetos_Ciclo2'!$B:$B,$C34,'Controle Projetos_Ciclo2'!$F:$F,"Total") -> 0 | I34: =SUMIFS('Controle Projetos_Ciclo2'!$R:$R,'Controle Projetos_Ciclo2'!$B:$B,$C34,'Controle Projetos_Ciclo2'!$F:$F,"Total") -> 0 | J34: =SUMIFS('Controle Projetos_Ciclo2'!S:S,'Controle Projetos_Ciclo2'!$B:$B,$C34,'Controle Projetos_Ciclo2'!$F:$F,"Total") -> 0 | K34: =IFERROR(I34/H34,0) -> 0 | M34: Construção - Serviços de Construção - NOVA MORADA
B35: =B34+1 -> 32 | C35: Pains 2 | D35: ESTRELA DO NORTE | E35: EDN | F35: 3 | G35: Apolo | H35: =SUMIFS('Controle Projetos_Ciclo2'!$O:$O,'Controle Projetos_Ciclo2'!$B:$B,$C35,'Controle Projetos_Ciclo2'!$F:$F,"Total") -> 0 | I35: =SUMIFS('Controle Projetos_Ciclo2'!$R:$R,'Controle Projetos_Ciclo2'!$B:$B,$C35,'Controle Projetos_Ciclo2'!$F:$F,"Total") -> 0 | J35: =SUMIFS('Controle Projetos_Ciclo2'!S:S,'Controle Projetos_Ciclo2'!$B:$B,$C35,'Controle Projetos_Ciclo2'!$F:$F,"Total") -> 0 | K35: =IFERROR(I35/H35,0) -> 0 | M35: Equipamentos Curva A - Contrato Sobressalentes - SETTA
... B40: =B39+1 -> 37 | C40: Paracatu 5 | D40: ESTRELA DO NORTE | E40: EDN | F40: 3 | G40: Apolo | H40: =SUMIFS('Controle Projetos_Ciclo2'!$O:$O,'Controle Projetos_Ciclo2'!$B:$B,$C40,'Controle Projetos_Ciclo2'!$F:$F,"Total") -> 0 | I40: =SUMIFS('Controle Projetos_Ciclo2'!$R:$R,'Controle Projetos_Ciclo2'!$B:$B,$C40,'Controle Projetos_Ciclo2'!$F:$F,"Total") -> 0 | J40: =SUMIFS('Controle Projetos_Ciclo2'!S:S,'Controle Projetos_Ciclo2'!$B:$B,$C40,'Controle Projetos_Ciclo2'!$F:$F,"Total") -> 0 | K40: =IFERROR(I40/H40,0) -> 0 | M40: *
B41: =B40+1 -> 38 | C41: Alfenas 4 | D41: MORI MINAS V | E41: NewCo V | F41: 2 | G41: Solatio | H41: =SUMIFS('Controle Projetos_Ciclo2'!$O:$O,'Controle Projetos_Ciclo2'!$B:$B,$C41,'Controle Projetos_Ciclo2'!$F:$F,"Total") -> 2771538.7 | I41: =SUMIFS('Controle Projetos_Ciclo2'!$R:$R,'Controle Projetos_Ciclo2'!$B:$B,$C41,'Controle Projetos_Ciclo2'!$F:$F,"Total") -> 2686059.9 | J41: =SUMIFS('Controle Projetos_Ciclo2'!S:S,'Controle Projetos_Ciclo2'!$B:$B,$C41,'Controle Projetos_Ciclo2'!$F:$F,"Total") -> 85478.84 | K41: =IFERROR(I41/H41,0) -> 0.96915835
B42: =B41+1 -> 39 | C42: Arcos 7 | D42: MORI MINAS IV | E42: NewCo IV | F42: 1 | G42: Solatio | H42: =SUMIFS('Controle Projetos_Ciclo2'!$O:$O,'Controle Projetos_Ciclo2'!$B:$B,$C42,'Controle Projetos_Ciclo2'!$F:$F,"Total") -> 0 | I42: =SUMIFS('Controle Projetos_Ciclo2'!$R:$R,'Controle Projetos_Ciclo2'!$B:$B,$C42,'Controle Projetos_Ciclo2'!$F:$F,"Total") -> 0 | J42: =SUMIFS('Controle Projetos_Ciclo2'!S:S,'Controle Projetos_Ciclo2'!$B:$B,$C42,'Controle Projetos_Ciclo2'!$F:$F,"Total") -> 0 | K42: =IFERROR(I42/H42,0) -> 0
B43: =B42+1 -> 40 | C43: Bambuí 1.1 | D43: MORI MINAS IV | E43: NewCo IV | F43: Weg | G43: Solatio | H43: =SUMIFS('Controle Projetos_Ciclo2'!$O:$O,'Controle Projetos_Ciclo2'!$B:$B,$C43,'Controle Projetos_Ciclo2'!$F:$F,"Total") -> 0 | I43: =SUMIFS('Controle Projetos_Ciclo2'!$R:$R,'Controle Projetos_Ciclo2'!$B:$B,$C43,'Controle Projetos_Ciclo2'!$F:$F,"Total") -> 0 | J43: =SUMIFS('Controle Projetos_Ciclo2'!S:S,'Controle Projetos_Ciclo2'!$B:$B,$C43,'Controle Projetos_Ciclo2'!$F:$F,"Total") -> 0 | K43: =IFERROR(I43/H43,0) -> 0
B44: =B43+1 -> 41 | C44: Bambuí 1.2 | D44: MORI MINAS V | E44: NewCo V | F44: Weg | G44: Solatio | H44: =SUMIFS('Controle Projetos_Ciclo2'!$O:$O,'Controle Projetos_Ciclo2'!$B:$B,$C44,'Controle Projetos_Ciclo2'!$F:$F,"Total") -> 0 | I44: =SUMIFS('Controle Projetos_Ciclo2'!$R:$R,'Controle Projetos_Ciclo2'!$B:$B,$C44,'Controle Projetos_Ciclo2'!$F:$F,"Total") -> 0 | J44: =SUMIFS('Controle Projetos_Ciclo2'!S:S,'Controle Projetos_Ciclo2'!$B:$B,$C44,'Controle Projetos_Ciclo2'!$F:$F,"Total") -> 0 | K44: =IFERROR(I44/H44,0) -> 0
B45: =B44+1 -> 42 | C45: Campo Belo 1 | D45: MORI MINAS IV | E45: NewCo IV | F45: 2 | G45: Solatio | H45: =SUMIFS('Controle Projetos_Ciclo2'!$O:$O,'Controle Projetos_Ciclo2'!$B:$B,$C45,'Controle Projetos_Ciclo2'!$F:$F,"Total") -> 0 | I45: =SUMIFS('Controle Projetos_Ciclo2'!$R:$R,'Controle Projetos_Ciclo2'!$B:$B,$C45,'Controle Projetos_Ciclo2'!$F:$F,"Total") -> 0 | J45: =SUMIFS('Controle Projetos_Ciclo2'!S:S,'Controle Projetos_Ciclo2'!$B:$B,$C45,'Controle Projetos_Ciclo2'!$F:$F,"Total") -> 0 | K45: =IFERROR(I45/H45,0) -> 0
...

Sheet Controle Projetos_Ciclo3
A1: N° | B1: UFV | C1: CNPJ | D1: Unidade | E1: Frente | F1: Natureza | G1: Portfólio | H1: Fornecedor | I1: Contrato original | J1: Aditivo 1 | K1: Aditivo 2 | L1: Aditivo 3 | M1: Aditivo 4 | N1: Aditivo 5 | O1: Valor total | P1: FD.Medido | Q1: Medição | R1: FD+Medição | S1: Saldo a Medir | T1: Avanço Contratual% | U1: Avanço OBRA% | V1: OBS:
A2: 1 | B2: Diamantina 1 | C2: MORI GERACAO II | D2: Mori II | E2: 3 | F2: Conexão AT - Obras | G2: Mori | H2: MBA | I2: 308990.19 | J2: 0 | K2: 0 | L2: 0 | M2: 0 | N2: 0 | O2: 308990.19
A3: 1 | B3: Diamantina 1 | C3: MORI GERACAO II | D3: Mori II | E3: 3 | F3: Conexão MT - Obras | G3: Mori | H3: MBA | I3: 735500 | J3: 0 | K3: 0 | L3: 0 | M3: 0 | N3: 0 | O3: 735500
A4: 1 | B4: Diamantina 1 | C4: MORI GERACAO II | D4: Mori II | E4: 3 | F4: Construção - Serviços de Construção | G4: Mori | H4: Implantar | I4: 2556450 | J4: 157000 | K4: 91704.15 | L4: 251404.62 | M4: 44129.95 | N4: 0 | O4: 3100688.7
A5: 1 | B5: Diamantina 1 | C5: MORI GERACAO II | D5: Mori II | E5: 3 | F5: Construção - Serviços de Construção - Substituição | G5: Mori | H5: 0 | I5: 0 | J5: 0 | K5: 0 | L5: 0 | M5: 0 | N5: 0 | O5: 0
A6: 1 | B6: Diamantina 1 | C6: MORI GERACAO II | D6: Mori II | E6: 3 | F6: Construção - RDA Interno | G6: Mori | H6: Eletrocamp | I6: 402477.3 | J6: 6400 | K6: 7304.5454 | L6: 0 | M6: 0 | N6: 0 | O6: 416182.01
A7: 1 | B7: Diamantina 1 | C7: MORI GERACAO II | D7: Mori II | E7: 3 | F7: Full EPC - Contrato | G7: Mori | H7: 0 | I7: 0 | J7: 0 | K7: 0 | L7: 0 | M7: 0 | N7: 0 | O7: 0
A8: 1 | B8: Diamantina 1 | C8: MORI GERACAO II | D8: Mori II | E8: 3 | F8: Equipamentos Curva A - Outros (Transformadores) | G8: Mori | H8: 0 | I8: 0 | J8: 0 | K8: 0 | L8: 0 | M8: 0 | N8: 0 | O8: 0
A9: 1 | B9: Diamantina 1 | C9: MORI GERACAO II | D9: Mori II | E9: 3 | F9: Equipamentos Curva A - Outros (Cabine + Skid) | G9: Mori | H9: 0 | I9: 0 | J9: 0 | K9: 0 | L9: 0 | M9: 0 | N9: 0 | O9: 0
A10: 1 | B10: Diamantina 1 | C10: MORI GERACAO II | D10: Mori II | E10: 3 | F10: Equipamentos Curva A - Outros (Cabine + Skid + Transformador) | G10: Mori | H10: Romagnole | I10: 1200784.7 | J10: 0 | K10: 0 | L10: 0 | M10: 0 | N10: 0 | O10: 1200784.7
A11: 1 | B11: Diamantina 1 | C11: MORI GERACAO II | D11: Mori II | E11: 3 | F11: Desenvolvimento de projeto - Projetos - (Eng° Proprietario) | G11: Mori | H11: LM Eng. | I11: 0 | J11: 0 | K11: 0 | L11: 0 | M11: 0 | N11: 0 | O11: 0
A12: 1 | B12: Diamantina 1 | C12: MORI GERACAO II | D12: Mori II | E12: 3 | F12: Desenvolvimento de projeto - Projetos - Executivos | G12: Mori | H12: Enersolar | I12: 36466.7 | J12: 0 | K12: 0 | L12: 0 | M12: 0 | N12: 0 | O12: 36466.7
A13: 1 | B13: Diamantina 1 | C13: MORI GERACAO II | D13: Mori II | E13: 3 | F13: Desenvolvimento de projeto - Projetos Básica | G13: Mori | H13: 0 | I13: 0 | J13: 0 | K13: 0 | L13: 0 | M13: 0 | N13: 0 | O13: 0
A14: 1 | B14: Diamantina 1 | C14: MORI GERACAO II | D14: Mori II | E14: 3 | F14: Desenvolvimento de projeto - Projetos Detalhada | G14: Mori | H14: GLD | I14: 93783 | J14: 42026.46 | K14: 0 | L14: 0 | M14: 0 | N14: 0 | O14: 135809.46
A15: 1 | B15: Diamantina 1 | C15: MORI GERACAO II | D15: Mori II | E15: 3 | F15: Desenvolvimento de projeto - Ambiental / Outros | G15: Mori | H15: Varios | I15: 155757.91 | J15: 0 | K15: 0 | L15: 0 | M15: 0 | N15: 0 | O15: 155757.91
A16: 1 | B16: Diamantina 1 | C16: MORI GERACAO II | D16: Mori II | E16: 3 | F16: Desenvolvimento de projeto - Coordenograma | G16: Mori | H16: PROJETTI | I16: 6207 | J16: 0 | K16: 0 | L16: 0 | M16: 0 | N16: 0 | O16: 6207
A17: 1 | B17: Diamantina 1 | C17: MORI GERACAO II | D17: Mori II | E17: 3 | F17: Sistemas de Monitoramento - Supervisório | G17: Mori | H17: ATI | I17: 136693.98 | K17: 0 | L17: 0 | M17: 0 | N17: 0 | O17: 136693.98
A18: 1 | B18: Diamantina 1 | C18: MORI GERACAO II | D18: Mori II | E18: 3 | F18: Sistemas de Monitoramento - Estações Solarimétricas | G18: Mori | H18: Hukseflux | I18: 48276.516 | J18: 0 | K18: 0 | L18: 0 | M18: 0 | N18: 0 | O18: 48276.516
A19: 1 | B19: Diamantina 1 | C19: MORI GERACAO II | D19: Mori II | E19: 3 | F19: Sistemas de Monitoramento - CFTV | G19: Mori | H19: Maxvision | I19: 248414.57 | J19: 0 | K19: 0 | L19: 0 | M19: 0 | N19: 0 | O19: 248414.57
A20: 1 | B20: Diamantina 1 | C20: MORI GERACAO II | D20: Mori II | E20: 3 | F20: Serviços Auxiliares - Drenagem | G20: Mori | H20: CONSPLAN / ORCI | I20: 839026.26 | J20: 293286.3 | K20: 188709 | L20: 0 | M20: 0 | N20: 0 | O20: 1321021.6
A21: 1 | B21: Diamantina 1 | C21: MORI GERACAO II | D21: Mori II | E21: 3 | F21: Serviços Auxiliares - Terraplanagem | G21: Mori | H21: MRO | I21: 1108130.6 | J21: 0 | K21: 0 | L21: 0 | M21: 0 | N21: 0 | O21: 1108130.6
A22: 1 | B22: Diamantina 1 | C22: MORI GERACAO II | D22: Mori II | E22: 3 | F22: Serviços Auxiliares - Supressão Vegetal | G22: Mori | H22: Rima | I22: 50000 | J22: 3500 | K22: 30000 | L22: 0 | M22: 0 | N22: 0 | O22: 83500
A23: 1 | B23: Diamantina 1 | C23: MORI GERACAO II | D23: Mori II | E23: 3 | F23: RDR-Rede de Distribuição Rural | G23: Mori | H23: 0 | I23: 0 | J23: 0 | K23: 0 | L23: 0 | M23: 0 | N23: 0 | O23: 0
A24: 1 | B24: Diamantina 1 | C24: MORI GERACAO II | D24: Mori II | E24: 3 | F24: Escopo COMERC | G24: Mori | H24: 0 | I24: 352962.83 | J24: 538750 | K24: 0 | L24: 0 | M24: 0 | N24: 0 | O24: 891712.83
A25: 1 | B25: Diamantina 1 | C25: MORI GERACAO II | D25: Mori II | E25: 3 | F25: Escopo COMERC - Segurança | G25: Mori | H25: 0 | I25: 94500 | J25: 0 | K25: 0 | L25: 0 | M25: 0 | N25: 0 | O25: 94500
A26: 1 | B26: Diamantina 1 | C26: MORI GERACAO II | D26: Mori II | E26: 3 | F26: Conexão MT - Obras Transferencia | G26: Mori | H26: ENGELUZ | I26: 3677500 | J26: 0 | K26: 0 | L26: 0 | M26: 0 | N26: 0 | O26: 3677500
A27: 1 | B27: Diamantina 1 | C27: MORI GERACAO II | D27: Mori II | E27: 3 | F27: Bases de Contaniers | G27: Mori | H27: 0 | I27: 0 | J27: 0 | K27: 0 | L27: 0 | M27: 0 | N27: 0 | O27: 0
A28: 1 | B28: Diamantina 1 | C28: MORI GERACAO II | D28: Mori II | E28: 3 | F28: Construção - Serviços de Construção - Ase Engenharia | G28: Mori | H28: 0 | I28: 0 | J28: 0 | K28: 0 | L28: 0 | M28: 0 | N28: 0 | O28: 0
A29: 1 | B29: Diamantina 1 | C29: MORI GERACAO II | D29: Mori II | E29: 3 | F29: Full EPC - Contrato Sobressalentes | G29: Mori | H29: 0 | I29: 0 | J29: 0 | K29: 0 | L29: 0 | M29: 0 | N29: 0 | O29: 0
A30: 1 | B30: Diamantina 1 | C30: MORI GERACAO II | D30: Mori II | E30: 3 | F30: Construção - Serviços de Construção - NOVA MORADA | G30: Mori | H30: 0 | I30: 0 | J30: 0 | K30: 0 | L30: 0 | M30: 0 | N30: 0 | O30: 0
A31: 1 | B31: Diamantina 1 | C31: MORI GERACAO II | D31: Mori II | E31: 3 | F31: Add. | G31: Mori | H31: 0 | I31: 0 | J31: 0 | K31: 0 | L31: 0 | M31: 0 | N31: 0 | O31: 0
A32: 1 | B32: Diamantina 1 | C32: MORI GERACAO II | D32: Mori II | E32: 3 | F32: Add. | G32: Mori | H32: 0 | I32: 0 | J32: 0 | K32: 0 | L32: 0 | M32: 0 | N32: 0 | O32: 0
A33: 1 | B33: Diamantina 1 | C33: MORI GERACAO II | D33: Mori II | E33: 3 | F33: Add. | G33: Mori | H33: 0 | I33: 0 | J33: 0 | K33: 0 | L33: 0 | M33: 0 | N33: 0 | O33: 0
A34: 1 | B34: Diamantina 1 | C34: MORI GERACAO II | D34: Mori II | E34: 3 | F34: Total | G34: Mori | I34: 3677500 | J34: 0 | K34: 0 | L34: 0 | M34: 0 | N34: 0 | O34: 3677500

Sheet GLD
D3: GLD
D4: MORI GERACAO II | E4: 111378.32 | F4: =E4 -> 111378.32
D5: EDN | E5: 4828
D6: EDN | E6: 4346.36
D7: EDN | E7: 40104.26
D8: EDN | E8: 122496.81 | F8: =SUM(E5:E8) -> 171775.43
D9: NewCo IV | E9: 50084.37
D10: NewCo IV | E10: 5373.56
D11: NewCo IV | E11: 9928.56
D12: NewCo IV | E12: 88298.31
D13: NewCo IV | E13: 5893.74
D14: NewCo IV | E14: 78094.07
D15: NewCo IV | E15: 0.0099999998
D16: NewCo IV | E16: 10.01
D17: NewCo IV | E17: 688958.09
D18: NewCo IV | E18: 578091.13 | F18: =SUM(E9:E18) -> 1504731.9
D19: NewCo V | E19: 10769.86
D20: NewCo V | E20: 7230.04
D21: NewCo V | E21: 424454.62
D22: NewCo V | E22: 0 | F22: =SUM(E19:E22) -> 442454.52
E24: Total: | F24: =SUM(F4:F22) -> 2230340.1

Sheet Controle Projetos_Ciclo2
A1: /;., 3 | B1: UFV | C1: CNPJ | D1: Unidade | E1: Frente | F1: Natureza | G1: Portfólio | H1: Fornecedor | I1: Contrato original | J1: Aditivo 1 | K1: Aditivo 2 | L1: Aditivo 3 | M1: Aditivo 4 | N1: Aditivo 5 | O1: Valor total | P1: FD.Medido | Q1: Medição | R1: FD+Medição | S1: Saldo a Medir | T1: Avanço Contratual% | U1: Pagamento? Sim / Não | V1: OBS:
A2: 1 | B2: =VLOOKUP($A2,Controle!$B$4:$F$68,2,FALSE) -> Diamantina 1 | C2: =VLOOKUP($A2,Controle!$B$4:$F$68,3,FALSE) -> MORI GERACAO II | D2: =VLOOKUP($A2,Controle!$B$4:$F$68,4,FALSE) -> Mori II | E2: =VLOOKUP($A2,Controle!$B$4:$F$68,5,FALSE) -> 3 | F2: Conexão AT - Obras | G2: =VLOOKUP($A2,Controle!$B$4:$G$68,6,FALSE) -> Mori | H2: MBA | I2: 308990.19 | J2: 0 | K2: 0 | L2: 0 | M2: 0 | N2: 0 | O2: =SUM(I2:N2) -> 308990.19 | P2: =SUMIFS('Desenvolvimento diário'!$H:$H,'Desenvolvimento diário'!$Q:$Q,$B2,'Desenvolvimento diário'!$P:$P,$F2,'Desenvolvimento diário'!$R:$R,"Sim") -> 99490.19 | Q2: =SUMIFS('Desenvolvimento diário'!$H:$H,'Desenvolvimento diário'!$Q:$Q,$B2,'Desenvolvimento diário'!$P:$P,$F2,'Desenvolvimento diário'!$R:$R,"Não") -> 209500 | R2: =SUM(P2:Q2) -> 308990.19 | S2: =O2-R2 -> 0 | T2: =IFERROR(R2/O2,0) -> 1
A3: =A2 -> 1 | B3: =VLOOKUP($A3,Controle!$B$4:$F$68,2,FALSE) -> Diamantina 1 | C3: =VLOOKUP($A3,Controle!$B$4:$F$68,3,FALSE) -> MORI GERACAO II | D3: =VLOOKUP($A3,Controle!$B$4:$F$68,4,FALSE) -> Mori II | E3: =VLOOKUP($A3,Controle!$B$4:$F$68,5,FALSE) -> 3 | F3: Conexão MT - Obras | G3: =VLOOKUP($A3,Controle!$B$4:$G$68,6,FALSE) -> Mori | H3: MBA | I3: 735500 | J3: =(-78468+0.23) -> -78467.77 | K3: 0 | L3: 0 | M3: 0 | N3: 0 | O3: =SUM(I3:N3) -> 657032.23 | P3: =SUMIFS('Desenvolvimento diário'!$H:$H,'Desenvolvimento diário'!$Q:$Q,$B3,'Desenvolvimento diário'!$P:$P,$F3,'Desenvolvimento diário'!$R:$R,"Sim") -> 197032.23 | Q3: =SUMIFS('Desenvolvimento diário'!$H:$H,'Desenvolvimento diário'!$Q:$Q,$B3,'Desenvolvimento diário'!$P:$P,$F3,'Desenvolvimento diário'!$R:$R,"Não") -> 460000 | R3: =SUM(P3:Q3) -> 657032.23 | S3: =O3-R3 -> 0 | T3: =IFERROR(R3/O3,0) -> 1
A4: =A3 -> 1 | B4: =VLOOKUP($A4,Controle!$B$4:$F$68,2,FALSE) -> Diamantina 1 | C4: =VLOOKUP($A4,Controle!$B$4:$F$68,3,FALSE) -> MORI GERACAO II | D4: =VLOOKUP($A4,Controle!$B$4:$F$68,4,FALSE) -> Mori II | E4: =VLOOKUP($A4,Controle!$B$4:$F$68,5,FALSE) -> 3 | F4: Construção - Serviços de Construção | G4: =VLOOKUP($A4,Controle!$B$4:$G$68,6,FALSE) -> Mori | H4: Implantar | I4: 2556450 | J4: 157000 | K4: 91704.15 | L4: 251404.62 | M4: 44129.95 | N4: 0 | O4: =SUM(I4:N4) -> 3100688.7 | P4: =SUMIFS('Desenvolvimento diário'!$H:$H,'Desenvolvimento diário'!$Q:$Q,$B4,'Desenvolvimento diário'!$P:$P,$F4,'Desenvolvimento diário'!$R:$R,"Sim") -> 1313672.7 | Q4: =SUMIFS('Desenvolvimento diário'!$H:$H,'Desenvolvimento diário'!$Q:$Q,$B4,'Desenvolvimento diário'!$P:$P,$F4,'Desenvolvimento diário'!$R:$R,"Não") -> 1778347.1 | R4: =SUM(P4:Q4) -> 3092019.8 | S4: =O4-R4 -> 8668.9 | T4: =IFERROR(R4/O4,0) -> 0.9972042 | U4: N | V4: Em Processo Judicial
A5: =A4 -> 1 | B5: =VLOOKUP($A5,Controle!$B$4:$F$68,2,FALSE) -> Diamantina 1 | C5: =VLOOKUP($A5,Controle!$B$4:$F$68,3,FALSE) -> MORI GERACAO II | D5: =VLOOKUP($A5,Controle!$B$4:$F$68,4,FALSE) -> Mori II | E5: =VLOOKUP($A5,Controle!$B$4:$F$68,5,FALSE) -> 3 | F5: Construção - Serviços de Construção - Substituição | G5: =VLOOKUP($A5,Controle!$B$4:$G$68,6,FALSE) -> Mori | H5: 0 | I5: 0 | J5: 0 | K5: 0 | L5: 0 | M5: 0 | N5: 0 | O5: =SUM(I5:N5) -> 0 | P5: =SUMIFS('Desenvolvimento diário'!$H:$H,'Desenvolvimento diário'!$Q:$Q,$B5,'Desenvolvimento diário'!$P:$P,$F5,'Desenvolvimento diário'!$R:$R,"Sim") -> 0 | Q5: =SUMIFS('Desenvolvimento diário'!$H:$H,'Desenvolvimento diário'!$Q:$Q,$B5,'Desenvolvimento diário'!$P:$P,$F5,'Desenvolvimento diário'!$R:$R,"Não") -> 0 | R5: =SUM(P5:Q5) -> 0 | S5: =O5-R5 -> 0 | T5: =IFERROR(R5/O5,0) -> 0
A6: =A5 -> 1 | B6: =VLOOKUP($A6,Controle!$B$4:$F$68,2,FALSE) -> Diamantina 1 | C6: =VLOOKUP($A6,Controle!$B$4:$F$68,3,FALSE) -> MORI GERACAO II | D6: =VLOOKUP($A6,Controle!$B$4:$F$68,4,FALSE) -> Mori II | E6: =VLOOKUP($A6,Controle!$B$4:$F$68,5,FALSE) -> 3 | F6: Construção - RDA Interno | G6: =VLOOKUP($A6,Controle!$B$4:$G$68,6,FALSE) -> Mori | H6: Eletrocamp | I6: 402477.3 | J6: 6400 | K6: 7304.5454 | L6: 0 | M6: 0 | N6: 0 | O6: =SUM(I6:N6)+0.1646 -> 416182.01 | P6: =SUMIFS('Desenvolvimento diário'!$H:$H,'Desenvolvimento diário'!$Q:$Q,$B6,'Desenvolvimento diário'!$P:$P,$F6,'Desenvolvimento diário'!$R:$R,"Sim") -> 0 | Q6: =SUMIFS('Desenvolvimento diário'!$H:$H,'Desenvolvimento diário'!$Q:$Q,$B6,'Desenvolvimento diário'!$P:$P,$F6,'Desenvolvimento diário'!$R:$R,"Não") -> 416182.01 | R6: =SUM(P6:Q6) -> 416182.01 | S6: =O6-R6 -> 0 | T6: =IFERROR(R6/O6,0) -> 1
A7: =A6 -> 1 | B7: =VLOOKUP($A7,Controle!$B$4:$F$68,2,FALSE) -> Diamantina 1 | C7: =VLOOKUP($A7,Controle!$B$4:$F$68,3,FALSE) -> MORI GERACAO II | D7: =VLOOKUP($A7,Controle!$B$4:$F$68,4,FALSE) -> Mori II | E7: =VLOOKUP($A7,Controle!$B$4:$F$68,5,FALSE) -> 3 | F7: Full EPC - Contrato | G7: =VLOOKUP($A7,Controle!$B$4:$G$68,6,FALSE) -> Mori | H7: 0 | I7: 0 | J7: 0 | K7: 0 | L7: 0 | M7: 0 | N7: 0 | O7: =SUM(I7:N7) -> 0 | P7: =SUMIFS('Desenvolvimento diário'!$H:$H,'Desenvolvimento diário'!$Q:$Q,$B7,'Desenvolvimento diário'!$P:$P,$F7,'Desenvolvimento diário'!$R:$R,"Sim") -> 0 | Q7: =SUMIFS('Desenvolvimento diário'!$H:$H,'Desenvolvimento diário'!$Q:$Q,$B7,'Desenvolvimento diário'!$P:$P,$F7,'Desenvolvimento diário'!$R:$R,"Não") -> 0 | R7: =SUM(P7:Q7) -> 0 | S7: =O7-R7 -> 0 | T7: =IFERROR(R7/O7,0) -> 0
A8: =A7 -> 1 | B8: =VLOOKUP($A8,Controle!$B$4:$F$68,2,FALSE) -> Diamantina 1 | C8: =VLOOKUP($A8,Controle!$B$4:$F$68,3,FALSE) -> MORI GERACAO II | D8: =VLOOKUP($A8,Controle!$B$4:$F$68,4,FALSE) -> Mori II | E8: =VLOOKUP($A8,Controle!$B$4:$F$68,5,FALSE) -> 3 | F8: Equipamentos Curva A - Outros (Transformadores) | G8: =VLOOKUP($A8,Controle!$B$4:$G$68,6,FALSE) -> Mori | H8: 0 | I8: 0 | J8: 0 | K8: 0 | L8: 0 | M8: 0 | N8: 0 | O8: =SUM(I8:N8) -> 0 | P8: =SUMIFS('Desenvolvimento diário'!$H:$H,'Desenvolvimento diário'!$Q:$Q,$B8,'Desenvolvimento diário'!$P:$P,$F8,'Desenvolvimento diário'!$R:$R,"Sim") -> 0 | Q8: =SUMIFS('Desenvolvimento diário'!$H:$H,'Desenvolvimento diário'!$Q:$Q,$B8,'Desenvolvimento diário'!$P:$P,$F8,'Desenvolvimento diário'!$R:$R,"Não") -> 0 | R8: =SUM(P8:Q8) -> 0 | S8: =O8-R8 -> 0 | T8: =IFERROR(R8/O8,0) -> 0
A9: =A8 -> 1 | B9: =VLOOKUP($A9,Controle!$B$4:$F$68,2,FALSE) -> Diamantina 1 | C9: =VLOOKUP($A9,Controle!$B$4:$F$68,3,FALSE) -> MORI GERACAO II | D9: =VLOOKUP($A9,Controle!$B$4:$F$68,4,FALSE) -> Mori II | E9: =VLOOKUP($A9,Controle!$B$4:$F$68,5,FALSE) -> 3 | F9: Equipamentos Curva A - Outros (Cabine + Skid) | G9: =VLOOKUP($A9,Controle!$B$4:$G$68,6,FALSE) -> Mori | H9: 0 | I9: 0 | J9: 0 | K9: 0 | L9: 0 | M9: 0 | N9: 0 | O9: =SUM(I9:N9) -> 0 | P9: =SUMIFS('Desenvolvimento diário'!$H:$H,'Desenvolvimento diário'!$Q:$Q,$B9,'Desenvolvimento diário'!$P:$P,$F9,'Desenvolvimento diário'!$R:$R,"Sim") -> 0 | Q9: =SUMIFS('Desenvolvimento diário'!$H:$H,'Desenvolvimento diário'!$Q:$Q,$B9,'Desenvolvimento diário'!$P:$P,$F9,'Desenvolvimento diário'!$R:$R,"Não") -> 0 | R9: =SUM(P9:Q9) -> 0 | S9: =O9-R9 -> 0 | T9: =IFERROR(R9/O9,0) -> 0
A10: =A9 -> 1 | B10: =VLOOKUP($A10,Controle!$B$4:$F$68,2,FALSE) -> Diamantina 1 | C10: =VLOOKUP($A10,Controle!$B$4:$F$68,3,FALSE) -> MORI GERACAO II | D10: =VLOOKUP($A10,Controle!$B$4:$F$68,4,FALSE) -> Mori II | E10: =VLOOKUP($A10,Controle!$B$4:$F$68,5,FALSE) -> 3 | F10: Equipamentos Curva A - Outros (Cabine + Skid + Transformador) | G10: =VLOOKUP($A10,Controle!$B$4:$G$68,6,FALSE) -> Mori | H10: Romagnole | I10: 1200784.7 | J10: 0 | K10: 0 | L10: 0 | M10: 0 | N10: 0 | O10: =SUM(I10:N10) -> 1200784.7 | P10: =SUMIFS('Desenvolvimento diário'!$H:$H,'Desenvolvimento diário'!$Q:$Q,$B10,'Desenvolvimento diário'!$P:$P,$F10,'Desenvolvimento diário'!$R:$R,"Sim") -> 0 | Q10: =SUMIFS('Desenvolvimento diário'!$H:$H,'Desenvolvimento diário'!$Q:$Q,$B10,'Desenvolvimento diário'!$P:$P,$F10,'Desenvolvimento diário'!$R:$R,"Não") -> 1200784.7 | R10: =SUM(P10:Q10) -> 1200784.7 | S10: =O10-R10 -> 0 | T10: =IFERROR(R10/O10,0) -> 1
A11: =A10 -> 1 | B11: =VLOOKUP($A11,Controle!$B$4:$F$68,2,FALSE) -> Diamantina 1 | C11: =VLOOKUP($A11,Controle!$B$4:$F$68,3,FALSE) -> MORI GERACAO II | D11: =VLOOKUP($A11,Controle!$B$4:$F$68,4,FALSE) -> Mori II | E11: =VLOOKUP($A11,Controle!$B$4:$F$68,5,FALSE) -> 3 | F11: Desenvolvimento de projeto - Projetos - (Eng° Proprietario) | G11: =VLOOKUP($A11,Controle!$B$4:$G$68,6,FALSE) -> Mori | H11: LM Eng. | I11: 0 | J11: 0 | K11: 0 | L11: 0 | M11: 0 | N11: 0 | O11: =SUM(I11:N11) -> 0 | P11: =SUMIFS('Desenvolvimento diário'!$H:$H,'Desenvolvimento diário'!$Q:$Q,$B11,'Desenvolvimento diário'!$P:$P,$F11,'Desenvolvimento diário'!$R:$R,"Sim") -> 0 | Q11: =SUMIFS('Desenvolvimento diário'!$H:$H,'Desenvolvimento diário'!$Q:$Q,$B11,'Desenvolvimento diário'!$P:$P,$F11,'Desenvolvimento diário'!$R:$R,"Não") -> 0 | R11: =SUM(P11:Q11) -> 0 | S11: =O11-R11 -> 0 | T11: =IFERROR(R11/O11,0) -> 0
A12: =A11 -> 1 | B12: =VLOOKUP($A12,Controle!$B$4:$F$68,2,FALSE) -> Diamantina 1 | C12: =VLOOKUP($A12,Controle!$B$4:$F$68,3,FALSE) -> MORI GERACAO II | D12: =VLOOKUP($A12,Controle!$B$4:$F$68,4,FALSE) -> Mori II | E12: =VLOOKUP($A12,Controle!$B$4:$F$68,5,FALSE) -> 3 | F12: Desenvolvimento de projeto - Projetos - Executivos | G12: =VLOOKUP($A12,Controle!$B$4:$G$68,6,FALSE) -> Mori | H12: Enersolar | I12: Feito com a GLD | J12: 0 | K12: 0 | L12: 0 | M12: 0 | N12: 0 | O12: =SUM(I12:N12) -> 0 | P12: =SUMIFS('Desenvolvimento diário'!$H:$H,'Desenvolvimento diário'!$Q:$Q,$B12,'Desenvolvimento diário'!$P:$P,$F12,'Desenvolvimento diário'!$R:$R,"Sim") -> 0 | Q12: =SUMIFS('Desenvolvimento diário'!$H:$H,'Desenvolvimento diário'!$Q:$Q,$B12,'Desenvolvimento diário'!$P:$P,$F12,'Desenvolvimento diário'!$R:$R,"Não") -> 0 | R12: =SUM(P12:Q12) -> 0 | S12: =O12-R12 -> 0 | T12: =IFERROR(R12/O12,0) -> 0
A13: =A12 -> 1 | B13: =VLOOKUP($A13,Controle!$B$4:$F$68,2,FALSE) -> Diamantina 1 | C13: =VLOOKUP($A13,Controle!$B$4:$F$68,3,FALSE) -> MORI GERACAO II | D13: =VLOOKUP($A13,Controle!$B$4:$F$68,4,FALSE) -> Mori II | E13: =VLOOKUP($A13,Controle!$B$4:$F$68,5,FALSE) -> 3 | F13: Desenvolvimento de projeto - Projetos Básica | G13: =VLOOKUP($A13,Controle!$B$4:$G$68,6,FALSE) -> Mori | H13: 0 | I13: 0 | J13: 0 | K13: 0 | L13: 0 | M13: 0 | N13: 0 | O13: =SUM(I13:N13) -> 0 | P13: =SUMIFS('Desenvolvimento diário'!$H:$H,'Desenvolvimento diário'!$Q:$Q,$B13,'Desenvolvimento diário'!$P:$P,$F13,'Desenvolvimento diário'!$R:$R,"Sim") -> 0 | Q13: =SUMIFS('Desenvolvimento diário'!$H:$H,'Desenvolvimento diário'!$Q:$Q,$B13,'Desenvolvimento diário'!$P:$P,$F13,'Desenvolvimento diário'!$R:$R,"Não") -> 0 | R13: =SUM(P13:Q13) -> 0 | S13: =O13-R13 -> 0 | T13: =IFERROR(R13/O13,0) -> 0
A14: =A13 -> 1 | B14: =VLOOKUP($A14,Controle!$B$4:$F$68,2,FALSE) -> Diamantina 1 | C14: =VLOOKUP($A14,Controle!$B$4:$F$68,3,FALSE) -> MORI GERACAO II | D14: =VLOOKUP($A14,Controle!$B$4:$F$68,4,FALSE) -> Mori II | E14: =VLOOKUP($A14,Controle!$B$4:$F$68,5,FALSE) -> 3 | F14: Desenvolvimento de projeto - Projetos Detalhada | G14: =VLOOKUP($A14,Controle!$B$4:$G$68,6,FALSE) -> Mori | H14: GLD | I14: 93783 | J14: 42026.46 | K14: 0 | L14: 0 | M14: 0 | N14: 0 | O14: =SUM(I14:N14) -> 135809.46 | P14: =SUMIFS('Desenvolvimento diário'!$H:$H,'Desenvolvimento diário'!$Q:$Q,$B14,'Desenvolvimento diário'!$P:$P,$F14,'Desenvolvimento diário'!$R:$R,"Sim") -> 0 | Q14: =SUMIFS('Desenvolvimento diário'!$H:$H,'Desenvolvimento diário'!$Q:$Q,$B14,'Desenvolvimento diário'!$P:$P,$F14,'Desenvolvimento diário'!$R:$R,"Não") -> 135809.46 | R14: =SUM(P14:Q14) -> 135809.46 | S14: =O14-R14 -> 0 | T14: =IFERROR(R14/O14,0) -> 1
A15: =A14 -> 1 | B15: =VLOOKUP($A15,Controle!$B$4:$F$68,2,FALSE) -> Diamantina 1 | C15: =VLOOKUP($A15,Controle!$B$4:$F$68,3,FALSE) -> MORI GERACAO II | D15: =VLOOKUP($A15,Controle!$B$4:$F$68,4,FALSE) -> Mori II | E15: =VLOOKUP($A15,Controle!$B$4:$F$68,5,FALSE) -> 3 | F15: Desenvolvimento de projeto - Ambiental / Outros | G15: =VLOOKUP($A15,Controle!$B$4:$G$68,6,FALSE) -> Mori | H15: Varios | I15: =R15 -> 177481.41 | J15: 0 | K15: 0 | L15: 0 | M15: 0 | N15: 0 | O15: =SUM(I15:N15) -> 177481.41 | P15: =SUMIFS('Desenvolvimento diário'!$H:$H,'Desenvolvimento diário'!$Q:$Q,$B15,'Desenvolvimento diário'!$P:$P,$F15,'Desenvolvimento diário'!$R:$R,"Sim") -> 0 | Q15: =SUMIFS('Desenvolvimento diário'!$H:$H,'Desenvolvimento diário'!$Q:$Q,$B15,'Desenvolvimento diário'!$P:$P,$F15,'Desenvolvimento diário'!$R:$R,"Não") -> 177481.41 | R15: =SUM(P15:Q15) -> 177481.41 | S15: =O15-R15 -> 0 | T15: =IFERROR(R15/O15,0) -> 1
A16: =A15 -> 1 | B16: =VLOOKUP($A16,Controle!$B$4:$F$68,2,FALSE) -> Diamantina 1 | C16: =VLOOKUP($A16,Controle!$B$4:$F$68,3,FALSE) -> MORI GERACAO II | D16: =VLOOKUP($A16,Controle!$B$4:$F$68,4,FALSE) -> Mori II | E16: =VLOOKUP($A16,Controle!$B$4:$F$68,5,FALSE) -> 3 | F16: Desenvolvimento de projeto - Coordenograma | G16: =VLOOKUP($A16,Controle!$B$4:$G$68,6,FALSE) -> Mori | H16: PROJETTI | I16: 6206.9 | J16: 0 | K16: 0 | L16: 0 | M16: 0 | N16: 0 | O16: =SUM(I16:N16) -> 6206.9 | P16: =SUMIFS('Desenvolvimento diário'!$H:$H,'Desenvolvimento diário'!$Q:$Q,$B16,'Desenvolvimento diário'!$P:$P,$F16,'Desenvolvimento diário'!$R:$R,"Sim") -> 0 | Q16: =SUMIFS('Desenvolvimento diário'!$H:$H,'Desenvolvimento diário'!$Q:$Q,$B16,'Desenvolvimento diário'!$P:$P,$F16,'Desenvolvimento diário'!$R:$R,"Não") -> 6206.9 | R16: =SUM(P16:Q16) -> 6206.9 | S16: =O16-R16 -> 0 | T16: =IFERROR(R16/O16,0) -> 1
A17: =A16 -> 1 | B17: =VLOOKUP($A17,Controle!$B$4:$F$68,2,FALSE) -> Diamantina 1 | C17: =VLOOKUP($A17,Controle!$B$4:$F$68,3,FALSE) -> MORI GERACAO II | D17: =VLOOKUP($A17,Controle!$B$4:$F$68,4,FALSE) -> Mori II | E17: =VLOOKUP($A17,Controle!$B$4:$F$68,5,FALSE) -> 3 | F17: Sistemas de Monitoramento - Supervisório | G17: =VLOOKUP($A17,Controle!$B$4:$G$68,6,FALSE) -> Mori | H17: ATI | I17: =136155.01-0.02 -> 136154.99 | K17: 0 | L17: 0 | M17: 0 | N17: 0 | O17: =SUM(I17:N17) -> 136154.99 | P17: =SUMIFS('Desenvolvimento diário'!$H:$H,'Desenvolvimento diário'!$Q:$Q,$B17,'Desenvolvimento diário'!$P:$P,$F17,'Desenvolvimento diário'!$R:$R,"Sim") -> 5821.02 | Q17: =SUMIFS('Desenvolvimento diário'!$H:$H,'Desenvolvimento diário'!$Q:$Q,$B17,'Desenvolvimento diário'!$P:$P,$F17,'Desenvolvimento diário'!$R:$R,"Não") -> 130333.97 | R17: =SUM(P17:Q17) -> 136154.99 | S17: =O17-R17 -> 0 | T17: =IFERROR(R17/O17,0) -> 1
A18: =A17 -> 1 | B18: =VLOOKUP($A18,Controle!$B$4:$F$68,2,FALSE) -> Diamantina 1 | C18: =VLOOKUP($A18,Controle!$B$4:$F$68,3,FALSE) -> MORI GERACAO II | D18: =VLOOKUP($A18,Controle!$B$4:$F$68,4,FALSE) -> Mori II | E18: =VLOOKUP($A18,Controle!$B$4:$F$68,5,FALSE) -> 3 | F18: Sistemas de Monitoramento - Estações Solarimétricas | G18: =VLOOKUP($A18,Controle!$B$4:$G$68,6,FALSE) -> Mori | H18: Hukseflux | I18: 48276.516 | J18: 0 | K18: 0 | L18: 0 | M18: 0 | N18: 0 | O18: =SUM(I18:N18) -> 48276.516 | P18: =SUMIFS('Desenvolvimento diário'!$H:$H,'Desenvolvimento diário'!$Q:$Q,$B18,'Desenvolvimento diário'!$P:$P,$F18,'Desenvolvimento diário'!$R:$R,"Sim") -> 0 | Q18: =SUMIFS('Desenvolvimento diário'!$H:$H,'Desenvolvimento diário'!$Q:$Q,$B18,'Desenvolvimento diário'!$P:$P,$F18,'Desenvolvimento diário'!$R:$R,"Não") -> 48276.516 | R18: =SUM(P18:Q18) -> 48276.516 | S18: =O18-R18 -> 0 | T18: =IFERROR(R18/O18,0) -> 1
A19: =A18 -> 1 | B19: =VLOOKUP($A19,Controle!$B$4:$F$68,2,FALSE) -> Diamantina 1 | C19: =VLOOKUP($A19,Controle!$B$4:$F$68,3,FALSE) -> MORI GERACAO II | D19: =VLOOKUP($A19,Controle!$B$4:$F$68,4,FALSE) -> Mori II | E19: =VLOOKUP($A19,Controle!$B$4:$F$68,5,FALSE) -> 3 | F19: Sistemas de Monitoramento - CFTV | G19: =VLOOKUP($A19,Controle!$B$4:$G$68,6,FALSE) -> Mori | H19: Maxvision | I19: 248414.57 | J19: 0 | K19: 10913.68 | L19: 0 | M19: 0 | N19: 0 | O19: =SUM(I19:N19) -> 259328.25 | P19: =SUMIFS('Desenvolvimento diário'!$H:$H,'Desenvolvimento diário'!$Q:$Q,$B19,'Desenvolvimento diário'!$P:$P,$F19,'Desenvolvimento diário'!$R:$R,"Sim") -> 0 | Q19: =SUMIFS('Desenvolvimento diário'!$H:$H,'Desenvolvimento diário'!$Q:$Q,$B19,'Desenvolvimento diário'!$P:$P,$F19,'Desenvolvimento diário'!$R:$R,"Não") -> 259328.25 | R19: =SUM(P19:Q19) -> 259328.25 | S19: =O19-R19 -> 0 | T19: =IFERROR(R19/O19,0) -> 1
A20: =A19 -> 1 | B20: =VLOOKUP($A20,Controle!$B$4:$F$68,2,FALSE) -> Diamantina 1 | C20: =VLOOKUP($A20,Controle!$B$4:$F$68,3,FALSE) -> MORI GERACAO II | D20: =VLOOKUP($A20,Controle!$B$4:$F$68,4,FALSE) -> Mori II | E20: =VLOOKUP($A20,Controle!$B$4:$F$68,5,FALSE) -> 3 | F20: Serviços Auxiliares - Drenagem | G20: =VLOOKUP($A20,Controle!$B$4:$G$68,6,FALSE) -> Mori | H20: CONSPLAN / ORCI / Engetela | I20: 839026.26 | J20: 293286.3 | K20: 188709 | L20: =82625+14190 -> 96815 | M20: 0 | N20: 0 | O20: =SUM(I20:N20) -> 1417836.6 | P20: =SUMIFS('Desenvolvimento diário'!$H:$H,'Desenvolvimento diário'!$Q:$Q,$B20,'Desenvolvimento diário'!$P:$P,$F20,'Desenvolvimento diário'!$R:$R,"Sim") -> 94354.5 | Q20: =SUMIFS('Desenvolvimento diário'!$H:$H,'Desenvolvimento diário'!$Q:$Q,$B20,'Desenvolvimento diário'!$P:$P,$F20,'Desenvolvimento diário'!$R:$R,"Não") -> 1323482.1 | R20: =SUM(P20:Q20) -> 1417836.6 | S20: =O20-R20 -> 0 | T20: =IFERROR(R20/O20,0) -> 1
A21: =A20 -> 1 | B21: =VLOOKUP($A21,Controle!$B$4:$F$68,2,FALSE) -> Diamantina 1 | C21: =VLOOKUP($A21,Controle!$B$4:$F$68,3,FALSE) -> MORI GERACAO II | D21: =VLOOKUP($A21,Controle!$B$4:$F$68,4,FALSE) -> Mori II | E21: =VLOOKUP($A21,Controle!$B$4:$F$68,5,FALSE) -> 3 | F21: Serviços Auxiliares - Terraplanagem | G21: =VLOOKUP($A21,Controle!$B$4:$G$68,6,FALSE) -> Mori | H21: MRO | I21: 1108130.6 | J21: 0 | K21: 0 | L21: 0 | M21: 0 | N21: 0 | O21: =SUM(I21:N21) -> 1108130.6 | P21: =SUMIFS('Desenvolvimento diário'!$H:$H,'Desenvolvimento diário'!$Q:$Q,$B21,'Desenvolvimento diário'!$P:$P,$F21,'Desenvolvimento diário'!$R:$R,"Sim") -> 0 | Q21: =SUMIFS('Desenvolvimento diário'!$H:$H,'Desenvolvimento diário'!$Q:$Q,$B21,'Desenvolvimento diário'!$P:$P,$F21,'Desenvolvimento diário'!$R:$R,"Não") -> 1108130.6 | R21: =SUM(P21:Q21) -> 1108130.6 | S21: =O21-R21 -> 0 | T21: =IFERROR(R21/O21,0) -> 1
A22: =A21 -> 1 | B22: =VLOOKUP($A22,Controle!$B$4:$F$68,2,FALSE) -> Diamantina 1 | C22: =VLOOKUP($A22,Controle!$B$4:$F$68,3,FALSE) -> MORI GERACAO II | D22: =VLOOKUP($A22,Controle!$B$4:$F$68,4,FALSE) -> Mori II | E22: =VLOOKUP($A22,Controle!$B$4:$F$68,5,FALSE) -> 3 | F22: Serviços Auxiliares - Supressão Vegetal | G22: =VLOOKUP($A22,Controle!$B$4:$G$68,6,FALSE) -> Mori | H22: Rima | I22: 50000 | J22: 3500 | K22: 30000 | L22: 0 | M22: 0 | N22: 0 | O22: =SUM(I22:N22) -> 83500 | P22: =SUMIFS('Desenvolvimento diário'!$H:$H,'Desenvolvimento diário'!$Q:$Q,$B22,'Desenvolvimento diário'!$P:$P,$F22,'Desenvolvimento diário'!$R:$R,"Sim") -> 0 | Q22: =SUMIFS('Desenvolvimento diário'!$H:$H,'Desenvolvimento diário'!$Q:$Q,$B22,'Desenvolvimento diário'!$P:$P,$F22,'Desenvolvimento diário'!$R:$R,"Não") -> 83500 | R22: =SUM(P22:Q22) -> 83500 | S22: =O22-R22 -> 0 | T22: =IFERROR(R22/O22,0) -> 1
A23: =A22 -> 1 | B23: =VLOOKUP($A23,Controle!$B$4:$F$68,2,FALSE) -> Diamantina 1 | C23: =VLOOKUP($A23,Controle!$B$4:$F$68,3,FALSE) -> MORI GERACAO II | D23: =VLOOKUP($A23,Controle!$B$4:$F$68,4,FALSE) -> Mori II | E23: =VLOOKUP($A23,Controle!$B$4:$F$68,5,FALSE) -> 3 | F23: RDR-Rede de Distribuição Rural | G23: =VLOOKUP($A23,Controle!$B$4:$G$68,6,FALSE) -> Mori | H23: 0 | I23: 0 | J23: 0 | K23: 0 | L23: 0 | M23: 0 | N23: 0 | O23: =SUM(I23:N23) -> 0 | P23: =SUMIFS('Desenvolvimento diário'!$H:$H,'Desenvolvimento diário'!$Q:$Q,$B23,'Desenvolvimento diário'!$P:$P,$F23,'Desenvolvimento diário'!$R:$R,"Sim") -> 0 | Q23: =SUMIFS('Desenvolvimento diário'!$H:$H,'Desenvolvimento diário'!$Q:$Q,$B23,'Desenvolvimento diário'!$P:$P,$F23,'Desenvolvimento diário'!$R:$R,"Não") -> 0 | R23: =SUM(P23:Q23) -> 0 | S23: =O23-R23 -> 0 | T23: =IFERROR(R23/O23,0) -> 0
A24: =A23 -> 1 | B24: =VLOOKUP($A24,Controle!$B$4:$F$68,2,FALSE) -> Diamantina 1 | C24: =VLOOKUP($A24,Controle!$B$4:$F$68,3,FALSE) -> MORI GERACAO II | D24: =VLOOKUP($A24,Controle!$B$4:$F$68,4,FALSE) -> Mori II | E24: =VLOOKUP($A24,Controle!$B$4:$F$68,5,FALSE) -> 3 | F24: Escopo COMERC | G24: =VLOOKUP($A24,Controle!$B$4:$G$68,6,FALSE) -> Mori | H24: 0 | I24: 552033.58 | J24: 59000 | K24: 0 | L24: 0 | M24: 0 | N24: 0 | O24: =SUM(I24:N24) -> 611033.58 | P24: =SUMIFS('Desenvolvimento diário'!$H:$H,'Desenvolvimento diário'!$Q:$Q,$B24,'Desenvolvimento diário'!$P:$P,$F24,'Desenvolvimento diário'!$R:$R,"Sim") -> 61688.6 | Q24: =SUMIFS('Desenvolvimento diário'!$H:$H,'Desenvolvimento diário'!$Q:$Q,$B24,'Desenvolvimento diário'!$P:$P,$F24,'Desenvolvimento diário'!$R:$R,"Não") -> 491343.76 | R24: =SUM(P24:Q24) -> 553032.36 | S24: =O24-R24 -> 58001.22 | T24: =IFERROR(R24/O24,0) -> 0.90507687 | U24: S | V24: Escopo Comerc
A25: =A24 -> 1 | B25: =VLOOKUP($A25,Controle!$B$4:$F$68,2,FALSE) -> Diamantina 1 | C25: =VLOOKUP($A25,Controle!$B$4:$F$68,3,FALSE) -> MORI GERACAO II | D25: =VLOOKUP($A25,Controle!$B$4:$F$68,4,FALSE) -> Mori II | E25: =VLOOKUP($A25,Controle!$B$4:$F$68,5,FALSE) -> 3 | F25: Escopo COMERC - Segurança | G25: =VLOOKUP($A25,Controle!$B$4:$G$68,6,FALSE) -> Mori | H25: 0 | I25: =R25 -> 231000 | J25: 0 | K25: 0 | L25: 0 | M25: 0 | N25: 0 | O25: =SUM(I25:N25) -> 231000 | P25: =SUMIFS('Desenvolvimento diário'!$H:$H,'Desenvolvimento diário'!$Q:$Q,$B25,'Desenvolvimento diário'!$P:$P,$F25,'Desenvolvimento diário'!$R:$R,"Sim") -> 0 | Q25: =SUMIFS('Desenvolvimento diário'!$H:$H,'Desenvolvimento diário'!$Q:$Q,$B25,'Desenvolvimento diário'!$P:$P,$F25,'Desenvolvimento diário'!$R:$R,"Não") -> 231000 | R25: =SUM(P25:Q25) -> 231000 | S25: =O25-R25 -> 0 | T25: =IFERROR(R25/O25,0) -> 1
A26: =A25 -> 1 | B26: =VLOOKUP($A26,Controle!$B$4:$F$68,2,FALSE) -> Diamantina 1 | C26: =VLOOKUP($A26,Controle!$B$4:$F$68,3,FALSE) -> MORI GERACAO II | D26: =VLOOKUP($A26,Controle!$B$4:$F$68,4,FALSE) -> Mori II | E26: =VLOOKUP($A26,Controle!$B$4:$F$68,5,FALSE) -> 3 | F26: Conexão MT - Obras Transferencia | G26: =VLOOKUP($A26,Controle!$B$4:$G$68,6,FALSE) -> Mori | H26: Engeluz | I26: 3677500 | J26: 1070080.4 | K26: 0 | L26: 0 | M26: 0 | N26: 0 | O26: =SUM(I26:N26) -> 4747580.4 | P26: =SUMIFS('Desenvolvimento diário'!$H:$H,'Desenvolvimento diário'!$Q:$Q,$B26,'Desenvolvimento diário'!$P:$P,$F26,'Desenvolvimento diário'!$R:$R,"Sim") -> 1711832.9 | Q26: =SUMIFS('Desenvolvimento diário'!$H:$H,'Desenvolvimento diário'!$Q:$Q,$B26,'Desenvolvimento diário'!$P:$P,$F26,'Desenvolvimento diário'!$R:$R,"Não") -> 3035747.5 | R26: =SUM(P26:Q26) -> 4747580.4 | S26: =O26-R26 -> 0 | T26: =IFERROR(R26/O26,0) -> 1
A27: =A26 -> 1 | B27: =VLOOKUP($A27,Controle!$B$4:$F$68,2,FALSE) -> Diamantina 1 | C27: =VLOOKUP($A27,Controle!$B$4:$F$68,3,FALSE) -> MORI GERACAO II | D27: =VLOOKUP($A27,Controle!$B$4:$F$68,4,FALSE) -> Mori II | E27: =VLOOKUP($A27,Controle!$B$4:$F$68,5,FALSE) -> 3 | F27: Bases de Contaniers | G27: =VLOOKUP($A27,Controle!$B$4:$G$68,6,FALSE) -> Mori | H27: 0 | I27: 0 | J27: 0 | K27: 0 | L27: 0 | M27: 0 | N27: 0 | O27: =SUM(I27:N27) -> 0 | P27: =SUMIFS('Desenvolvimento diário'!$H:$H,'Desenvolvimento diário'!$Q:$Q,$B27,'Desenvolvimento diário'!$P:$P,$F27,'Desenvolvimento diário'!$R:$R,"Sim") -> 0 | Q27: =SUMIFS('Desenvolvimento diário'!$H:$H,'Desenvolvimento diário'!$Q:$Q,$B27,'Desenvolvimento diário'!$P:$P,$F27,'Desenvolvimento diário'!$R:$R,"Não") -> 0 | R27: =SUM(P27:Q27) -> 0 | S27: =O27-R27 -> 0 | T27: =IFERROR(R27/O27,0) -> 0
A28: =A27 -> 1 | B28: =VLOOKUP($A28,Controle!$B$4:$F$68,2,FALSE) -> Diamantina 1 | C28: =VLOOKUP($A28,Controle!$B$4:$F$68,3,FALSE) -> MORI GERACAO II | D28: =VLOOKUP($A28,Controle!$B$4:$F$68,4,FALSE) -> Mori II | E28: =VLOOKUP($A28,Controle!$B$4:$F$68,5,FALSE) -> 3 | F28: Construção - Serviços de Construção - Ase Engenharia | G28: =VLOOKUP($A28,Controle!$B$4:$G$68,6,FALSE) -> Mori | H28: 0 | I28: 0 | J28: 0 | K28: 0 | L28: 0 | M28: 0 | N28: 0 | O28: =SUM(I28:N28) -> 0 | P28: =SUMIFS('Desenvolvimento diário'!$H:$H,'Desenvolvimento diário'!$Q:$Q,$B28,'Desenvolvimento diário'!$P:$P,$F28,'Desenvolvimento diário'!$R:$R,"Sim") -> 0 | Q28: =SUMIFS('Desenvolvimento diário'!$H:$H,'Desenvolvimento diário'!$Q:$Q,$B28,'Desenvolvimento diário'!$P:$P,$F28,'Desenvolvimento diário'!$R:$R,"Não") -> 0 | R28: =SUM(P28:Q28) -> 0 | S28: =O28-R28 -> 0 | T28: =IFERROR(R28/O28,0) -> 0
A29: =A28 -> 1 | B29: =VLOOKUP($A29,Controle!$B$4:$F$68,2,FALSE) -> Diamantina 1 | C29: =VLOOKUP($A29,Controle!$B$4:$F$68,3,FALSE) -> MORI GERACAO II | D29: =VLOOKUP($A29,Controle!$B$4:$F$68,4,FALSE) -> Mori II | E29: =VLOOKUP($A29,Controle!$B$4:$F$68,5,FALSE) -> 3 | F29: Full EPC - Contrato Sobressalentes | G29: =VLOOKUP($A29,Controle!$B$4:$G$68,6,FALSE) -> Mori | H29: 0 | I29: 0 | J29: 0 | K29: 0 | L29: 0 | M29: 0 | N29: 0 | O29: =SUM(I29:N29) -> 0 | P29: =SUMIFS('Desenvolvimento diário'!$H:$H,'Desenvolvimento diário'!$Q:$Q,$B29,'Desenvolvimento diário'!$P:$P,$F29,'Desenvolvimento diário'!$R:$R,"Sim") -> 0 | Q29: =SUMIFS('Desenvolvimento diário'!$H:$H,'Desenvolvimento diário'!$Q:$Q,$B29,'Desenvolvimento diário'!$P:$P,$F29,'Desenvolvimento diário'!$R:$R,"Não") -> 0 | R29: =SUM(P29:Q29) -> 0 | S29: =O29-R29 -> 0 | T29: =IFERROR(R29/O29,0) -> 0
A30: =A29 -> 1 | B30: =VLOOKUP($A30,Controle!$B$4:$F$68,2,FALSE) -> Diamantina 1 | C30: =VLOOKUP($A30,Controle!$B$4:$F$68,3,FALSE) -> MORI GERACAO II | D30: =VLOOKUP($A30,Controle!$B$4:$F$68,4,FALSE) -> Mori II | E30: =VLOOKUP($A30,Controle!$B$4:$F$68,5,FALSE) -> 3 | F30: Construção - Serviços de Construção - NOVA MORADA | G30: =VLOOKUP($A30,Controle!$B$4:$G$68,6,FALSE) -> Mori | H30: 0 | I30: 0 | J30: 0 | K30: 0 | L30: 0 | M30: 0 | N30: 0 | O30: =SUM(I30:N30) -> 0 | P30: =SUMIFS('Desenvolvimento diário'!$H:$H,'Desenvolvimento diário'!$Q:$Q,$B30,'Desenvolvimento diário'!$P:$P,$F30,'Desenvolvimento diário'!$R:$R,"Sim") -> 0 | Q30: =SUMIFS('Desenvolvimento diário'!$H:$H,'Desenvolvimento diário'!$Q:$Q,$B30,'Desenvolvimento diário'!$P:$P,$F30,'Desenvolvimento diário'!$R:$R,"Não") -> 0 | R30: =SUM(P30:Q30) -> 0 | S30: =O30-R30 -> 0 | T30: =IFERROR(R30/O30,0) -> 0
A31: =A30 -> 1 | B31: =VLOOKUP($A31,Controle!$B$4:$F$68,2,FALSE) -> Diamantina 1 | C31: =VLOOKUP($A31,Controle!$B$4:$F$68,3,FALSE) -> MORI GERACAO II | D31: =VLOOKUP($A31,Controle!$B$4:$F$68,4,FALSE) -> Mori II | E31: =VLOOKUP($A31,Controle!$B$4:$F$68,5,FALSE) -> 3 | F31: Equipamentos Curva A - Contrato Sobressalentes - SETTA | G31: =VLOOKUP($A31,Controle!$B$4:$G$68,6,FALSE) -> Mori | H31: 0 | I31: 0 | J31: 0 | K31: 0 | L31: 0 | M31: 0 | N31: 0 | O31: =SUM(I31:N31) -> 0 | P31: =SUMIFS('Desenvolvimento diário'!$H:$H,'Desenvolvimento diário'!$Q:$Q,$B31,'Desenvolvimento diário'!$P:$P,$F31,'Desenvolvimento diário'!$R:$R,"Sim") -> 0 | Q31: =SUMIFS('Desenvolvimento diário'!$H:$H,'Desenvolvimento diário'!$Q:$Q,$B31,'Desenvolvimento diário'!$P:$P,$F31,'Desenvolvimento diário'!$R:$R,"Não") -> 0 | R31: =SUM(P31:Q31) -> 0 | S31: =O31-R31 -> 0 | T31: =IFERROR(R31/O31,0) -> 0
A32: =A31 -> 1 | B32: =VLOOKUP($A32,Controle!$B$4:$F$68,2,FALSE) -> Diamantina 1 | C32: =VLOOKUP($A32,Controle!$B$4:$F$68,3,FALSE) -> MORI GERACAO II | D32: =VLOOKUP($A32,Controle!$B$4:$F$68,4,FALSE) -> Mori II | E32: =VLOOKUP($A32,Controle!$B$4:$F$68,5,FALSE) -> 3 | F32: Equipamentos Curva A - Contrato Sobressalentes - Arctech | G32: =VLOOKUP($A32,Controle!$B$4:$G$68,6,FALSE) -> Mori | H32: 0 | I32: 0 | J32: 0 | K32: 0 | L32: 0 | M32: 0 | N32: 0 | O32: =SUM(I32:N32) -> 0 | P32: =SUMIFS('Desenvolvimento diário'!$H:$H,'Desenvolvimento diário'!$Q:$Q,$B32,'Desenvolvimento diário'!$P:$P,$F32,'Desenvolvimento diário'!$R:$R,"Sim") -> 0 | Q32: =SUMIFS('Desenvolvimento diário'!$H:$H,'Desenvolvimento diário'!$Q:$Q,$B32,'Desenvolvimento diário'!$P:$P,$F32,'Desenvolvimento diário'!$R:$R,"Não") -> 0 | R32: =SUM(P32:Q32) -> 0 | S32: =O32-R32 -> 0 | T32: =IFERROR(R32/O32,0) -> 0
A33: =A30 -> 1 | B33: =VLOOKUP($A33,Controle!$B$4:$F$68,2,FALSE) -> Diamantina 1 | C33: =VLOOKUP($A33,Controle!$B$4:$F$68,3,FALSE) -> MORI GERACAO II | D33: =VLOOKUP($A33,Controle!$B$4:$F$68,4,FALSE) -> Mori II | E33: =VLOOKUP($A33,Controle!$B$4:$F$68,5,FALSE) -> 3 | F33: Equipamentos Curva A - Contrato Sobressalentes - Romagnole | G33: =VLOOKUP($A33,Controle!$B$4:$G$68,6,FALSE) -> Mori | H33: Onix | I33: 72399.64 | J33: 90503.03 | K33: 0 | L33: 0 | M33: 0 | N33: 0 | O33: =SUM(I33:N33) -> 162902.67 | P33: =SUMIFS('Desenvolvimento diário'!$H:$H,'Desenvolvimento diário'!$Q:$Q,$B33,'Desenvolvimento diário'!$P:$P,$F33,'Desenvolvimento diário'!$R:$R,"Sim") -> 0 | Q33: =SUMIFS('Desenvolvimento diário'!$H:$H,'Desenvolvimento diário'!$Q:$Q,$B33,'Desenvolvimento diário'!$P:$P,$F33,'Desenvolvimento diário'!$R:$R,"Não") -> 162902.67 | R33: =SUM(P33:Q33) -> 162902.67 | S33: =O33-R33 -> 0 | T33: =IFERROR(R33/O33,0) -> 1
A34: =A31 -> 1 | B34: =VLOOKUP($A34,Controle!$B$4:$F$68,2,FALSE) -> Diamantina 1 | C34: =VLOOKUP($A34,Controle!$B$4:$F$68,3,FALSE) -> MORI GERACAO II | D34: =VLOOKUP($A34,Controle!$B$4:$F$68,4,FALSE) -> Mori II | E34: =VLOOKUP($A34,Controle!$B$4:$F$68,5,FALSE) -> 3 | F34: GOS FLORESTAL - (PRAD - Recuperação Area Ambiental) | G34: =VLOOKUP($A34,Controle!$B$4:$G$68,6,FALSE) -> Mori | H34: Gos Florestal | I34: 426240 | K34: 0 | L34: 0 | M34: 0 | N34: 0 | O34: =SUM(I34:N34) -> 426240 | P34: =SUMIFS('Desenvolvimento diário'!$H:$H,'Desenvolvimento diário'!$Q:$Q,$B34,'Desenvolvimento diário'!$P:$P,$F34,'Desenvolvimento diário'!$R:$R,"Sim") -> 0 | Q34: =SUMIFS('Desenvolvimento diário'!$H:$H,'Desenvolvimento diário'!$Q:$Q,$B34,'Desenvolvimento diário'!$P:$P,$F34,'Desenvolvimento diário'!$R:$R,"Não") -> 426240 | R34: =SUM(P34:Q34) -> 426240 | S34: =O34-R34 -> 0 | T34: =IFERROR(R34/O34,0) -> 1 | U34: S | V34: GOS - Esse refere-se ao Contrato aprovado junto com acerto das Drenagens
